Workbook

Sheet articles_2026_01_26
A1: rayyan_key | B1: title | C1: year | D1: month | E1: day | F1: journal | G1: issn | H1: volume | I1: issue | J1: pages | K1: authors | L1: url | M1: language | N1: publisher | O1: location | P1: abstract | Q1: notes | R1: doi | S1: keywords | T1: pubmed_id | U1: pmc_id
A2: rayyan-83177405 | B2: Collaborative Adaptive Rangeland Management Fosters Management-Science Partnerships | C2: 2018 | F2: Rangeland Ecology & Management | G2: 1550-7424 | H2: 71 | I2: 5 | J2: 646-657 | K2: Wilmer H and Derner J D and Fernandez-Gimenez M E and Briske D D and Augustine D J and Porensky L M and Grp Carm Stakeholder | L2: <Go to ISI>://WOS:000446859300014 | Q2: Wilmer, Hailey Derner, Justin D. Fernandez-Gimenez, Maria E. Briske, David D. Augustine, David J. Porensky, Lauren M. Augustine, David/0000-0003-3144-0466; Derner, Justin/0000-0001-8076-0736; Fernandez-Gimenez, Maria/0000-0001-9641-1434 1551-5028 | RAYYAN-INCLUSION: {"Philip"=>"Excluded", "fereshteh"=>"Excluded", "Iris"=>"Included", "Sarah"=>"Included", "Nibedita"=>"Maybe", "Alec"=>"Included", "Alvaro"=>"Included"} | R2: 10.1016/j.rama.2017.07.008 | S2: eppi-reviewer
A3: rayyan-83177406 | B3: Entomological Society of America and Science Policy Engagement | C3: 2019 | F3: Annals of the Entomological Society of America | H3: 112 | I3: 2 | J3: 62-70 | K3: Wiedenmann Robert N and Zalom Frank G and Cadwalader Erin L and Alleyne Marianne and Stelzig Chris J | L3: http://0-search.ebscohost.com.catalogue.libraries.london.ac.uk/login.aspx?direct=true&db=a9h&AN=135201611&site=ehost-live | Q3: Wiedenmann, Robert N 1; Email Address: rwieden@uark.edu Zalom, Frank G 2 Cadwalader, Erin L 3 Alleyne, Marianne 4 Stelzig, Chris J 5; Affiliation: 1: Department of Entomology, University of Arkansas, Fayetteville, AR 2: Department of Entomology and Nematology, University of California, Davis, CA 3: Lewis-Burke Associates LLC, Washington, DC 4: Department of Entomology, University of Illinois, Urbana, IL 5: Entomological Society of America, Annapolis, MD; Source Info: Mar2019, Vol. 112 Issue 2, p62; Subject Term: ENTOMOLOGISTS; Subject Term: ENTOMOLOGY; Subject Term: SCIENCE &amp; state; Author-Supplied Keyword: Grand Challenges; Author-Supplied Keyword: policy fellows; Author-Supplied Keyword: science advocacy; Company/Entity: ENTOMOLOGICAL Society of America Company/Entity: UNITED States. Environmental Protection Agency; NAICS/Industry Codes: 541690 Other Scientific and Technical Consulting Services; NAICS/Industry Codes: 924110 Administration of Air and Water Resource and Solid Waste Management Programs; Number of Pages: 9p; Document Type: Article; Full Text Word Count: 8597 | RAYYAN-INCLUSION: {"Philip"=>"Excluded", "Nibedita"=>"Excluded", "Alec"=>"Excluded", "Alvaro"=>"Excluded"} | R3: 10.1093/aesa/say060 | S3: eppi-reviewer;ENTOMOLOGISTS ENTOMOLOGY SCIENCE &;tate Grand Challenge;policy fellow;cience advocacy ENTOMOLOGICAL Society of America UNITED State;Environmental Protection Agency
A4: rayyan-83177407 | B4: The need for transformative changes in the use of Indigenous knowledge along with science for environmental decision-making in the Arctic | C4: 2020 | F4: People and Nature | H4: 2 | I4: 3 | J4: 544-556 | K4: Wheeler H C and Danielsen F and Fidel M and Hausner V and Horstkotte T and Johnson N and Lee O and Mukherjee N and Amos A and Ashthorn H and Ballari O and Behe C and Breton-Honeyman K and Retter G B and Buschman V and Jakobsen P and Johnson F and Lyberth B and Parrott J A and Pogodaev M and Sulyandziga R and Vronski N | L4: <Go to ISI>://WOS:000647696100003 | Q4: Wheeler, Helen C. Danielsen, Finn Fidel, Maryann Hausner, Vera Horstkotte, Tim Johnson, Noor Lee, Olivia Mukherjee, Nibedita Amos, Amy Ashthorn, Heather Ballari, Oystein Behe, Carolina Breton-Honeyman, Kaitlin Retter, Gunn-Britt Buschman, Victoria Jakobsen, Paviarak Johnson, Frank Lyberth, Bjarne Parrott, Jennifer A. Pogodaev, Mikhail Sulyandziga, Rodion Vronski, Nikita Mukherjee, Nibedita/B-2531-2010 Mukherjee, Nibedita/0000-0002-2970-1498; Behe, Carolina/0000-0002-8141-8550; Hausner, Vera Helene/0000-0001-9825-0419; Wheeler, Helen/0000-0002-9820-5818 2575-8314 | RAYYAN-INCLUSION: {"Matthew"=>"Excluded", "Philip"=>"Excluded", "fereshteh"=>"Excluded", "Aidan"=>"Excluded", "Nibedita"=>"Included", "Alec"=>"Included", "Alvaro"=>"Excluded"} | R4: 10.1002/pan3.10131 | S4: eppi-reviewer
A5: rayyan-83177408 | B5: Increasing the uptake of ecological model results in policy decisions to improve biodiversity outcomes | C5: 2022 | F5: Environmental Modelling & Software | G5: 1364-8152 | H5: 149 | K5: Weiskopf S R and Harmackova Z V and Johnson C G and Londono-Murcia M C and Miller B W and Myers B J. E and Pereira L and Arce-Plata M I and Blanchard J L and Ferrier S and Fulton E A and Harfoot M and Isbell F and Johnson J A and Mori A S and Weng E S and Rosa I M. D | L5: <Go to ISI>://WOS:000787109500005 | Q5: Weiskopf, Sarah R. Harmackova, Zuzana, V Johnson, Ciara G. Londono-Murcia, Maria Cecilia Miller, Brian W. Myers, Bonnie J. E. Pereira, Laura Arce-Plata, Maria Isabel Blanchard, Julia L. Ferrier, Simon Fulton, Elizabeth A. Harfoot, Mike Isbell, Forest Johnson, Justin A. Mori, Akira S. Weng, Ensheng Rosa, Isabel M. D. Miller, Brian/0000-0003-1716-1161; Isbell, Forest/0000-0001-9689-769X; Weiskopf, Sarah/0000-0002-5933-8191 1873-6726 | RAYYAN-INCLUSION: {"Matthew"=>"Excluded", "Philip"=>"Included", "Alice"=>"Excluded", "Carlos"=>"Excluded", "Tabitha"=>"Included", "Prishnee"=>"Included", "Valentin"=>"Excluded", "Elina"=>"Included", "fereshteh"=>"Excluded", "Aidan"=>"Included", "Tiff"=>"Excluded", "Iris"=>"Included", "Sarah"=>"Excluded", "Nibedita"=>"Included", "Alec"=>"Excluded", "Alvaro"=>"Excluded", "Isobel"=>"Included"} | R5: 10.1016/j.envsoft.2022.105318 | S5: eppi-reviewer
A6: rayyan-83177409 | B6: Blueprints of Effective Biodiversity and Conservation Knowledge Products That Support Marine Policy | C6: 2017 | F6: Frontiers in Marine Science | H6: 4 | K6: Weatherdon L V and Appeltans W and Bowles-Newark N and Brooks T M and Davis F E and Despot-Belmonte K and Fletcher S and Garilao C and Hilton-Taylor C and Hirsch T and Juffe-Bignoli D and Kaschner K and Kingston N and Malsch K and Regan E C and Kesner-Reyes K and Rose D C and Wetzel F T and Wilkinson T and Martin C S | L6: <Go to ISI>://WOS:000457690600096 | Q6: Weatherdon, Lauren V. Appeltans, Ward Bowles-Newark, Nadine Brooks, Thomas M. Davis, Frances E. Despot-Belmonte, Katherine Fletcher, Stephen Garilao, Cristina Hilton-Taylor, Craig Hirsch, Tim Juffe-Bignoli, Diego Kaschner, Kristin Kingston, Naomi Malsch, Kelly Regan, Eugenie C. Kesner-Reyes, Kathleen Rose, David C. Wetzel, Florian T. Wilkinson, Tim Martin, Corinne S. ; Martin, Corinne/G-9041-2011 Weatherdon, Lauren V./0000-0002-3989-027X; Rose, David/0000-0002-5249-9021; Hirsch, Tim/0000-0002-5015-5807; Fletcher, Stephen/0000-0003-1180-9844; Martin, Corinne/0000-0002-5428-2766; Kaschner, Kristin/0000-0002-4061-626X 2296-7745 | RAYYAN-INCLUSION: {"Matthew"=>"Excluded", "Philip"=>"Excluded", "Alice"=>"Excluded", "Carlos"=>"Excluded", "Tabitha"=>"Excluded", "Prishnee"=>"Excluded", "Valentin"=>"Excluded", "Elina"=>"Excluded", "fereshteh"=>"Included", "Aidan"=>"Excluded", "Tiff"=>"Included", "Iris"=>"Excluded", "Sarah"=>"Excluded", "Nibedita"=>"Excluded", "Alec"=>"Excluded", "Isobel"=>"Excluded"} | R6: 10.3389/fmars.2017.00096 | S6: eppi-reviewer
A7: rayyan-83177410 | B7: EKLIPSE: engaging knowledge holders and networks for evidence-informed European policy on biodiversity and ecosystem services | C7: 2019 | F7: Evidence & Policy | G7: 1744-2648 | H7: 15 | I7: 2 | J7: 253-264 | K7: Watt A and Ainsworth G and Balian E and Cojocaru G and Darbi M and Dicks L and Eggermont H and Furman E and Goudeseune L and Huybrecht P and Kelemen E and Koch F and Konstantinou Z and Livoreil B and Locher K and Lux A and Mehring M and Nesshoever C and Paloniemi R and Saarikoski H and Pinto I S and Vandewalle M and Varjopuro R and Varumo L and Wittmer H and Young J | L7: <Go to ISI>://WOS:000471772800006 | Q7: Watt, Allan Ainsworth, Gill Balian, Estelle Cojocaru, George Darbi, Marianne Dicks, Lynn Eggermont, Hilde Furman, Eeva Goudeseune, Lise Huybrecht, Pierre Kelemen, Eszter Koch, Florian Konstantinou, Zoi Livoreil, Barbara Locher, Karla Lux, Alexandra Mehring, Marion Nesshoever, Carsten Paloniemi, Riikka Saarikoski, Heti Pinto, Isabel Sousa Vandewalle, Marie Varjopuro, Riku Varumo, Liisa Wittmer, Heidi Young, Juliette Pinto, Isabel Sousa/W-1591-2019; Wittmer, Heidi/H-7264-2012; Dicks, Lynn/AFH-5289-2022; Young, Juliette/B-4225-2012; Koch, Florian/F-2504-2015; Ainsworth, Gill/P-3013-2019 Pinto, Isabel Sousa/0000-0002-9231-0553; Wittmer, Heidi/0000-0001-6966-7258; Young, Juliette/0000-0002-8522-0883; Koch, Florian/0000-0002-0343-0730; Ainsworth, Gill/0000-0003-0460-6563; Goudeseune, Lise/0000-0002-4239-3338; Lux, Alexandra/0000-0002-6626-7977; Vandewalle, Marie/0000-0003-3619-9763; Cojocaru, George/0000-0002-1432-364X; Dicks, Lynn/0000-0002-8304-4468 1744-2656 | RAYYAN-INCLUSION: {"Matthew"=>"Excluded", "Philip"=>"Excluded", "Alice"=>"Excluded", "Carlos"=>"Excluded", "Tabitha"=>"Excluded", "Prishnee"=>"Excluded", "Valentin"=>"Excluded", "Elina"=>"Excluded", "fereshteh"=>"Included", "Aidan"=>"Excluded", "Tiff"=>"Excluded", "Iris"=>"Excluded", "Sarah"=>"Excluded", "Nibedita"=>"Excluded", "Alec"=>"Excluded", "Isobel"=>"Excluded"} | R7: 10.1332/174426418x15314036194114 | S7: eppi-reviewer
A8: rayyan-83177411 | B8: Characteristics of participatory monitoring projects and their relationship to decision-making in biological resource management: a review | C8: 2016 | F8: Biodiversity and Conservation | G8: 0960-3115 | H8: 25 | I8: 11 | J8: 2001-2019 | K8: Villasenor E and Porter-Bolland L and Escobar F and Guariguata M R and Moreno-Casasola P | L8: <Go to ISI>://WOS:000382014400001 | Q8: Villasenor, Emma Porter-Bolland, Luciana Escobar, Federico Guariguata, Manuel R. Moreno-Casasola, Patricia VILLASEÃ‘OR, EMMA/AAR-7143-2021; Escobar, Federico/C-1396-2011; Porter-Bolland, Luciana/C-1398-2016; Moreno-Casasola, Patricia/R-8562-2018; Bolland, Luciana Porter/AAH-4895-2020 Escobar, Federico/0000-0003-0179-7528; Porter-Bolland, Luciana/0000-0001-8586-3267; Moreno-Casasola, Patricia/0000-0003-0468-0851; Bolland, Luciana Porter/0000-0001-8586-3267 1572-9710 | RAYYAN-INCLUSION: {"Philip"=>"Excluded", "fereshteh"=>"Excluded", "Sarah"=>"Excluded", "Nibedita"=>"Excluded", "Alec"=>"Excluded"} | R8: 10.1007/s10531-016-1184-9 | S8: eppi-reviewer
A9: rayyan-83177413 | B9: What do scientists and managers know about soil biodiversity? Comparative knowledge mapping for sustainable forest management | C9: 2020 | F9: Forest Policy and Economics | G9: 1389-9341 | H9: 119 | K9: Vanermen I and Muys B and Verheyen K and Vanwindekens F and Bouriaud L and Kardol P and Vranken L | L9: <Go to ISI>://WOS:000568682900010 | Q9: Vanermen, Iris Muys, Bart Verheyen, Kris Vanwindekens, Frederic Bouriaud, Laura Kardol, Paul Vranken, Liesbet Kardol, Paul/N-8383-2015; Vranken, Liesbet/Q-1710-2018; BITOUN, RACHEL/AAC-9538-2021; Muys, Bart/A-3194-2015 Kardol, Paul/0000-0001-7065-3435; Vranken, Liesbet/0000-0003-1170-1139; Muys, Bart/0000-0001-9421-527X; Vanwindekens, Frederic/0000-0002-9117-7543 1872-7050 | RAYYAN-INCLUSION: {"Philip"=>"Excluded", "Alice"=>"Excluded", "fereshteh"=>"Excluded", "Nibedita"=>"Excluded", "Alec"=>"Excluded"} | R9: 10.1016/j.forpol.2020.102264 | S9: eppi-reviewer
A10: rayyan-83177414 | B10: A question of dissemination: Assessing the practices and implications of research in tropical landscapes | C10: 2019 | F10: AMBIO - A Journal of the Human Environment | H10: 48 | I10: 1 | J10: 35-47 | K10: Toomey Anne H and Alvaro MarÃ­a Eugenia Copa and Aiello-Lammens Matthew and Loayza Cossio and Oscar and Barlow Jos | L10: http://0-search.ebscohost.com.catalogue.libraries.london.ac.uk/login.aspx?direct=true&db=a9h&AN=133611999&site=ehost-live | Q10: Toomey, Anne H. 1; Email Address: atoomey@pace.edu Alvaro, MarÃ­a Eugenia Copa 2 Aiello-Lammens, Matthew 1 Loayza Cossio, Oscar 3 Barlow, Jos 4; Affiliation: 1: Department of Environmental Studies and Science, Pace University, 41 Park Row, #721B, 10038, New York, NY, USA 2: ColecciÃ³n Boliviana de Fauna, Calle 26 de Cota Cota (Ovidio SuÃ¡rez) Casilla NÂº 8706, La Paz, Bolivia 3: Madidi-Tambopata Landscape Conservation Program, Wildlife Conservation Society, Casilla 3-35Â 181 SM, La Paz, Bolivia 4: Lancaster Environment Centre, Lancaster University, LA1 4YQ, Bailrigg, Lancashire, UK; Source Info: Jan2019, Vol. 48 Issue 1, p35; Subject Term: SCIENTIFIC knowledge; Subject Term: CONSERVATIONISTS; Subject Term: ENVIRONMENTAL management; Subject Term: UNIVERSITIES &amp; colleges; Subject Term: PARQUE Nacional Madidi (Bolivia); Author-Supplied Keyword: Conservation management; Author-Supplied Keyword: Knowledge exchange; Author-Supplied Keyword: Local perceptions; Author-Supplied Keyword: Research ethics; Author-Supplied Keyword: Research-action; Author-Supplied Keyword: Research-implementation; NAICS/Industry Codes: 611310 Colleges, Universities, and Professional Schools; Number of Pages: 13p; Document Type: Article; Full Text Word Count: 7345 | RAYYAN-INCLUSION: {"Philip"=>"Included", "Tabitha"=>"Included", "fereshteh"=>"Excluded", "Iris"=>"Included", "Alec"=>"Included"} | R10: 10.1007/s13280-018-1056-5 | S10: eppi-reviewer;SCIENTIFIC knowledge CONSERVATIONISTS ENVIRONMENTAL management UNIVERSITIES & college;PARQUE Nacional Madidi (Bolivia) Con;ervation management Knowledge exchange Local perception;Re;earch ethic;earch-action Re;earch-implementation
A11: rayyan-83177415 | B11: lEvaluating the outcomes and processes of a research-action partnership: The need for continuous reflective evaluation | C11: 2016 | F11: Bothalia | G11: 0006-8241 | H11: 46 | I11: 2 | K11: Taylor C and Cockburn J and Rouget M and Ray-Mukherjee J and Mukherjee S and Slotow R and Roberts D and Boon R and O'Donoghue S and Douwes E | L11: <Go to ISI>://WOS:000389715000011 | Q11: Taylor, Chantal Cockburn, Jessica Rouget, Mathieu Ray-Mukherjee, Jayanti Mukherjee, Shomen Slotow, Rob Roberts, Debra Boon, Richard O'Donoghue, Sean Douwes, Errol Slotow, Rob/AAM-9053-2020 2311-9284 Si | RAYYAN-INCLUSION: {"Philip"=>"Included", "Tabitha"=>"Included", "fereshteh"=>"Excluded", "Alec"=>"Excluded"} | R11: 10.4102/abc.v46i2.2154 | S11: eppi-reviewer
A12: rayyan-83177416 | B12: Researchâ€“management partnerships: An opportunity to integrate genetics in conservation actions | C12: 2020 | F12: Conservation Science & Practice | H12: 2 | I12: 9 | J12: 46235 | K12: Taft Heather R and McCoskey Dana N and Miller Joshua M and Pearson Sarah K and Coleman Melinda A and Fletcher Nicholas K and Mittan Cinnamon S and Meek Mariah H and Barbosa Soraia | L12: http://0-search.ebscohost.com.catalogue.libraries.london.ac.uk/login.aspx?direct=true&db=a9h&AN=145430044&site=ehost-live | Q12: Taft, Heather R. 1 McCoskey, Dana N. 2 Miller, Joshua M. 3 Pearson, Sarah K. 4 Coleman, Melinda A. 5,6 Fletcher, Nicholas K. 7 Mittan, Cinnamon S. 7 Meek, Mariah H. 8 Barbosa, Soraia 9; Email Address: soraia.barbosa02@gmail.com; Affiliation: 1: Colorado State University Global, Aurora Colorado, USA 2: DC Audubon Society, Washington District of Columbia, USA 3: Department of Biological Sciences, University of Alberta, Edmonton Alberta,, Canada 4: College of Science and Engineering, Flinders University of South Australia, Adelaide South Australia,, Australia 5: Department of Primary Industries NSW Fisheries, National Marine Science Centre, Coffs Harbour New South Wales,, Australia 6: National Marine Science Centre, Southern Cross University, Coffs Harbour New South Wales,, Australia 7: Department of Ecology and Evolutionary Biology, Cornell University, Corson Hall, Ithaca New York, USA 8: Department of Integrative Biology, Michigan State University, East Lansing Michigan, USA 9: Department of Fish and Wildlife Sciences, University of Idaho, Moscow Idaho, USA; Source Info: Sep2020, Vol. 2 Issue 9, p1; Subject Term: CONSERVATION genetics; Subject Term: CONSERVATION biology; Subject Term: BUSINESS partnerships; Subject Term: DATA analysis; Subject Term: STRATEGIC planning; Author-Supplied Keyword: conservation genetics; Author-Supplied Keyword: management; Author-Supplied Keyword: partnerships; Author-Supplied Keyword: researchâ€implementation gap; Number of Pages: 8p; Document Type: Article; Full Text Word Count: 5054 | RAYYAN-INCLUSION: {"Matthew"=>"Included", "Philip"=>"Included", "Alice"=>"Excluded", "Carlos"=>"Included", "Tabitha"=>"Included", "Prishnee"=>"Included", "Valentin"=>"Included", "Elina"=>"Included", "fereshteh"=>"Excluded", "Aidan"=>"Included", "Tiff"=>"Included", "Iris"=>"Included", "Sarah"=>"Included", "Nibedita"=>"Included", "Alec"=>"Included", "Isobel"=>"Included"} | R12: 10.1111/csp2.218 | S12: eppi-reviewer;CONSERVATION genetic;CONSERVATION biology BUSINESS partner;hip;DATA analy;i;STRATEGIC planning management partner;re;earchâ€implementation gap
A13: rayyan-83177418 | B13: Challenges and opportunities of engaging biodiversity-related citizen science data in environmental decision-making: Practitioners' perceptions and a database analysis from Estonia | C13: 2021 | F13: Journal for Nature Conservation | G13: 1617-1381 | H13: 64 | K13: Suskevics M and Raadom T and Vanem B and Kana S and Roasto R and Runnel V and Kulvik M | L13: <Go to ISI>://WOS:000709046700010 | Q13: Suskevics, Monika Raadom, Terje Vanem, Brenda Kana, Silja Roasto, Reigo Runnel, Veljo Kulvik, Mart SuÅ¡keviÄs, Monika/H-3666-2017 SuÅ¡keviÄs, Monika/0000-0002-5666-2623 1618-1093 | RAYYAN-INCLUSION: {"Matthew"=>"Included", "Philip"=>"Included", "Alice"=>"Included", "Carlos"=>"Included", "Tabitha"=>"Included", "Prishnee"=>"Included", "Valentin"=>"Included", "Elina"=>"Included", "fereshteh"=>"Excluded", "Aidan"=>"Included", "Tiff"=>"Included", "Iris"=>"Included", "Sarah"=>"Included", "Nibedita"=>"Maybe", "Alec"=>"Included", "Isobel"=>"Included"} | R13: 10.1016/j.jnc.2021.126068 | S13: eppi-reviewer
A14: rayyan-83177420 | B14: Experiences from a National Landscape Monitoring ProgrammeMaintaining Continuity Whilst Meeting Changing Demands and Opportunities | C14: 2019 | F14: Land | H14: 8 | I14: 5 | K14: Stokstad G and Fjellstad W | L14: <Go to ISI>://WOS:000472659100005 | Q14: Stokstad, Grete Fjellstad, Wendy Fjellstad, Wendy/AAF-6257-2020 Fjellstad, Wendy Jane/0000-0002-2849-9785 2073-445x | RAYYAN-INCLUSION: {"Philip"=>"Excluded", "fereshteh"=>"Excluded", "Iris"=>"Included", "Alec"=>"Excluded"} | R14: 10.3390/land8050077 | S14: eppi-reviewer
A15: rayyan-83177421 | B15: Unblocking the flow of biodiversity data for decision-making in Africa | C15: 2017 | F15: Biological Conservation | H15: 213 | J15: 335-340 | K15: Stephenson P J and Bowles-Newark Nadine and Regan Eugenie and Stanwell-Smith Damon and Diagana MallÃ© and HÃ¶ft Robert and Abarchi Harouna and Abrahamse Tanya and Akello Christine and Allison Hilary and Banki Olaf and Batieno Barthelemy and Dieme Samuel and Domingos Arthur and Galt Russell and Githaiga Cicilia W and Guindo Abdoulaye Bine and Hafashimana David L N and Hirsch Tim and Hobern Donald | L15: http://0-search.ebscohost.com.catalogue.libraries.london.ac.uk/login.aspx?direct=true&db=a9h&AN=124610497&site=ehost-live | Q15: Stephenson, P.J. 1; Email Address: StephensonPJ@gmail.com Bowles-Newark, Nadine 2; Email Address: Nadine.Bowles-Newark@unep-wcmc.org Regan, Eugenie 2; Email Address: eugenie.regan@gmail.com Stanwell-Smith, Damon 2; Email Address: stanwellsmith@gmail.com Diagana, MallÃ© 3; Email Address: malle.diagana@iucn.org HÃ¶ft, Robert 4; Email Address: robert.hoft@cbd.int Abarchi, Harouna 5; Email Address: ab_harou@yahoo.fr Abrahamse, Tanya 6; Email Address: abrahamse@sanbi.org Akello, Christine 7; Email Address: cakelloechookit@yahoo.com Allison, Hilary 2; Email Address: Hilary.Allison@unep-wcmc.org Banki, Olaf 8; Email Address: Olaf@Banki.nl Batieno, Barthelemy 9; Email Address: barthelemy.batieno@iucn.org Dieme, Samuel 10; Email Address: sam_casa@yahoo.fr Domingos, Arthur 11; Email Address: aristofanesp@yahoo.com.br Galt, Russell 6; Email Address: R.Galt@sanbi.org.za Githaiga, Cicilia W. 12; Email Address: cgithaiga@nema.go.ke Guindo, Abdoulaye Bine 13; Email Address: abdoulayebine@yahoo.fr Hafashimana, David L.N. 7; Email Address: davidhaf2000@yahoo.com Hirsch, Tim 8; Email Address: thirsch@gbif.org Hobern, Donald 8; Email Address: dhobern@gbif.org; Affiliation: 1: WWF International, Gland, Switzerland 2: United Nations Environment Programme World Conservation Monitoring Centre (UNEP-WCMC), Cambridge, UK 3: WWF West Africa Marine Programme Office, Dakar, Senegal 4: Secretariat of the Convention on Biological Diversity, Montreal, Canada 5: Commission Technique sur la DiversitÃ© Biologique, Niamey, Niger 6: South African National Biodiversity Institute (SANBI), Pretoria, South Africa 7: National Environment Management Authority, Kampala, Uganda 8: Global Biodiversity Information Facility (GBIF), Copenhagen, Denmark 9: IUCN, Nouakchott, Mauritania 10: MinistÃ¨re de l'Environnement et de la Protection de la Nature, Dakar, Senegal 11: Ministry of Environment, Luanda, Angola 12: National Environment Management Authority, Nairobi, Kenya 13: MinistÃ¨re de l'Environnement, de l'Eau et de l'Assainissement, Bamako, Mali; Source Info: Sep2017 Part B, Vol. 213, p335; Subject Term: BIODIVERSITY conservation; Subject Term: DECISION making in environmental policy; Subject Term: ENVIRONMENTAL degradation; Subject Term: SUSTAINABLE development; Subject Term: GOVERNMENT agencies; Author-Supplied Keyword: Africa; Author-Supplied Keyword: Biodiversity; Author-Supplied Keyword: Data management; Author-Supplied Keyword: Environmental decision-making; NAICS/Industry Codes: 913910 Other local, municipal and regional public administration; NAICS/Industry Codes: 911910 Other federal government public administration; NAICS/Industry Codes: 912910 Other provincial and territorial public administration; NAICS/Industry Codes: 921190 Other General Government Support; NAICS/Industry Codes: 926110 Administration of General Economic Programs; Number of Pages: 6p; Document Type: Article | RAYYAN-INCLUSION: {"Matthew"=>"Included", "Philip"=>"Included", "Alice"=>"Included", "Carlos"=>"Included", "Tabitha"=>"Included", "Prishnee"=>"Included", "Valentin"=>"Included", "Elina"=>"Included", "fereshteh"=>"Excluded", "Aidan"=>"Included", "Tiff"=>"Included", "Iris"=>"Included", "Sarah"=>"Included", "Nibedita"=>"Included", "Alec"=>"Included", "Isobel"=>"Included"} | R15: 10.1016/j.biocon.2016.09.003 | S15: eppi-reviewer;BIODIVERSITY con;ervation DECISION making in environmental policy ENVIRONMENTAL degradation SUSTAINABLE developmen...;Africa Biodiver;ity Data management Environmental deci;ion-making
A16: rayyan-83177422 | B16: Exploring the usefulness of scenario archetypes in science-policy processes: experience across IPBES assessments | C16: 2019 | F16: Ecology and Society | G16: 1708-3087 | H16: 24 | I16: 3 | K16: Sitas N and Harmackova Z V and Anticamara J A and Arneth A and Badola R and Biggs R and Blanchard R and Brotons L and Cantele M and Coetzer K and DasGupta R and den Belder E and Ghosh S and Guisan A and Gundimeda H and Hamann M and Harrison P A and Hashimoto S and Hauck J and Klatt B J and Kok K and Krug R M and Niamir A and O'Farrell P J and Okayasu S and Palomo I and Pereira L M and Riordan P and Santos-Martin F and Selomane O and Shin Y J and Valle M | L16: <Go to ISI>://WOS:000490942000017 | Q16: Sitas, Nadia Harmackova, Zuzana V. Anticamara, Jonathan A. Arneth, Almut Badola, Ruchi Biggs, Reinette Blanchard, Ryan Brotons, Lluis Cantele, Matthew Coetzer, Kaera DasGupta, Rajarshi den Belder, Eefje Ghosh, Sonali Guisan, Antoine Gundimeda, Haripriya Hamann, Maike Harrison, Paula A. Hashimoto, Shizuka Hauck, Jennifer Klatt, Brian J. Kok, Kasper Krug, Rainer M. Niamir, Aidin O'Farrell, Patrick J. Okayasu, Sana Palomo, Ignacio Pereira, Laura M. Riordan, Philip Santos-Martin, Fernando Selomane, Odirilwe Shin, Yunne-Jai Valle, Mireia blanchard, ryan/B-8856-2017; Shin, Yunne-Jai/A-7575-2012; Guisan, Antoine/A-1057-2011; Dasgupta, Rajarshi/AAF-7822-2021; Niamir, Aidin/G-5779-2011; HASHIMOTO, Shizuka/P-5317-2019; Riordan, Philip/AAY-6420-2020; Arneth, Almut/B-2702-2013; DasGupta, Rajarshi/AAX-2695-2021; Pereira, Laura M./L-7258-2013; Biggs, Reinette/A-5155-2010; O'Farrell, Patrick/AAQ-7728-2021; Hauck, Jennifer/P-4115-2017; Selomane, Odirilwe/L-8068-2019; PALOMO, IGNACIO/D-4398-2014; HarmÃ¡ÄkovÃ¡, Zuzana V./G-1886-2014; Valle, Mireia/G-5783-2011 blanchard, ryan/0000-0002-3560-4133; Shin, Yunne-Jai/0000-0002-7259-9265; Guisan, Antoine/0000-0002-3998-4815; Niamir, Aidin/0000-0003-4511-3407; HASHIMOTO, Shizuka/0000-0003-4423-9374; Arneth, Almut/0000-0001-6616-0822; DasGupta, Rajarshi/0000-0003-0051-5090; Pereira, Laura M./0000-0002-4996-7234; Biggs, Reinette/0000-0003-0300-4149; O'Farrell, Patrick/0000-0002-9538-8831; Hauck, Jennifer/0000-0002-1614-9657; Selomane, Odirilwe/0000-0002-6892-4221; PALOMO, IGNACIO/0000-0002-4573-5989; HarmÃ¡ÄkovÃ¡, Zuzana V./0000-0001-7711-4135; Okayasu, Sana/0000-0002-6534-0458; Santos Martin, Fernando/0000-0002-2301-5876; Sitas, Nadia/0000-0003-0888-8617; Kok, Kasper/0000-0002-6319-9227; Riordan, Philip/0000-0001-6285-8596; Valle, Mireia/0000-0001-8517-8518 | RAYYAN-INCLUSION: {"Philip"=>"Included", "Alice"=>"Included", "fereshteh"=>"Included", "Alec"=>"Excluded"} | R16: 10.5751/es-11039-240335 | S16: eppi-reviewer
A17: rayyan-83177423 | B17: The role and value of science in shark conservation advocacy | C17: 2021 | F17: Scientific Reports | H17: 11 | I17: 1 | J17: 16626-16626 | K17: Shiffman D S and Macdonald C C and Wallace S S and Dulvy N K | L17: https://ovidsp.ovid.com/ovidweb.cgi?T=JS&CSC=Y&NEWS=N&PAGE=fulltext&D=med19&AN=34404844 https://discover.lshtm.ac.uk/openurl/44HYG/44HYG_services_page?sid=OVID:medline&id=doi:10.1038%2Fs41598-021-96020-4&id=pmid34404844&issn=2045-2322&isbn=&volume=11&issue=1&spage=16626&pages=16626&date=2021&title=Scientific+Reports&atitle=The+role+and+value+of+science+in+shark+conservation+advocacy.&aulast=Shiffman&pid=%3Cauthor%3EShiffman+DS%3BMacdonald+CC%3BWallace+SS%3BDulvy+NK%3C%2Fauthor%3E%3CAN%3E34404844 | O17: Shiffman, David S. Earth to Oceans Group, Department of Biological Sciences, Simon Fraser University | Q17: Shiffman, David S Macdonald, Catherine C Wallace, S Scott Dulvy, Nicholas K | RAYYAN-INCLUSION: {"Matthew"=>"Included", "Philip"=>"Included", "Alice"=>"Included", "Carlos"=>"Excluded", "Tabitha"=>"Excluded", "Prishnee"=>"Excluded", "Valentin"=>"Included", "Elina"=>"Excluded", "fereshteh"=>"Included", "Aidan"=>"Included", "Tiff"=>"Excluded", "Iris"=>"Excluded", "Sarah"=>"Included", "Nibedita"=>"Included", "Alec"=>"Included", "Isobel"=>"Included"} | S17: eppi-reviewer
A18: rayyan-83177424 | B18: Harnessing the Power of Community Science to Address Data Gaps in Arctic Observing: Invasive Species in Alaska as Case Examples | C18: 2021 | F18: Arctic Journal | H18: 74 | J18: 41640 | K18: Schwoerer Tobias and Spellman Katie V and Davis Tammy J and Lee Olivia and Martin Aaron and Mulder Christa P H and Swenson Nicole Y and Taylor Audrey and Winter Genelle | L18: http://0-search.ebscohost.com.catalogue.libraries.london.ac.uk/login.aspx?direct=true&db=a9h&AN=153358032&site=ehost-live | Q18: Schwoerer, Tobias 1; Email Address: tschwoerer@alaska.edu Spellman, Katie V. 1 Davis, Tammy J. 2 Lee, Olivia 1 Martin, Aaron 3 Mulder, Christa P. H. 4 Swenson, Nicole Y. 5 Taylor, Audrey 6 Winter, Genelle 7; Affiliation: 1: International Arctic Research Center, University of Alaska Fairbanks, 2160 North Koyukuk Drive, Fairbanks, Alaska 99775, USA 2: Alaska Department of Fish and Game, 1255 West 8th Street, Juneau, Alaska 99801, USA 3: U.S. Fish and Wildlife Service, 1011 East Tudor Road, Anchorage, Alaska 99503, USA 4: Institute of Arctic Biology and Department of Biology and Wildlife, University of Alaska Fairbanks, 2140 North Koyukuk Drive, Fairbanks, Alaska 99775, USA 5: Tyonek Tribal Conservation District, 1689 C Street, Suite 219, Anchorage, Alaska 99501, USA 6: Department of Biological Sciences, University of Alaska Anchorage, 3211 Providence Drive, Anchorage, Alaska 99508, USA 7: Metlakatla Indian Community, PO Box 8, Metlakatla, Alaska 99926, USA; Source Info: 2021 Supplement, Vol. 74, p1; Subject Term: INTRODUCED organisms; Subject Term: DATA science; Subject Term: COMMUNITY-based programs; Subject Term: CITIZEN science; Subject Term: BIOLOGICAL invasions; Subject Term: FOOD security; Subject Term: ECOSYSTEMS; Subject Term: ARCTIC regions; Subject Term: ALASKA; Author-Supplied Keyword: alien species; Author-Supplied Keyword: Arctic observing; Author-Supplied Keyword: citizen science; Author-Supplied Keyword: community science; Author-Supplied Keyword: early detection; Author-Supplied Keyword: evidence-based policy; Author-Supplied Keyword: monitoring; Author-Supplied Keyword: dÃ©tection prÃ©coce; Author-Supplied Keyword: espÃ¨ces Ã©trangÃ¨res; Author-Supplied Keyword: observation de l'Arctique; Author-Supplied Keyword: politique fondÃ©e sur des donnÃ©es probantes; Author-Supplied Keyword: science citoyenne; Author-Supplied Keyword: science communautaire; Author-Supplied Keyword: surveillance; Language of Keywords: English; Language of Keywords: French; Number of Pages: 14p; Document Type: Article | RAYYAN-INCLUSION: {"Philip"=>"Excluded", "fereshteh"=>"Included", "Aidan"=>"Excluded", "Alec"=>"Excluded"} | R18: 10.14430/arctic73773 | S18: eppi-reviewer;INTRODUCED organi;m;DATA;cience COMMUNITY-ba;ed program;CITIZEN;cience BIOLOGICAL inva;ion;FOOD;ecurity ECOSYSTEMS ARCTIC region;ALASKA alien;pecie;Arctic ob;erving community;cience early detection evidence-ba;ed policy monitoring dÃ©tection prÃ©coce e;pÃ¨ce;Ã©trangÃ¨re;ob;ervation de l'Arctique politique fondÃ©e;ur de;donnÃ©e;probante;cience citoyenne;cience communautaire;urveillance
A19: rayyan-83177427 | B19: Adopting Citizen Science as a Tool to Enhance Monitoring for an Environment Agency | C19: 2019 | F19: Citizen Science: Theory & Practice | H19: 6 | I19: 1 | J19: 46266 | K19: Roger Erin and Turak Eren and Tegart Patrick | L19: http://0-search.ebscohost.com.catalogue.libraries.london.ac.uk/login.aspx?direct=true&db=a9h&AN=140757826&site=ehost-live | Q19: Roger, Erin 1; Email Address: erin.roger@csiro.au Turak, Eren 1 Tegart, Patrick 1; Affiliation: 1: NSW Office of Environment and Heritage, AU; Source Info: 2019, Vol. 6 Issue 1, p1; Subject Term: CITIZEN science; Subject Term: ACQUISITION of data; Subject Term: DECISION making; Subject Term: PILOT projects; Subject Term: COMMUNITY involvement; Author-Supplied Keyword: barriers; Author-Supplied Keyword: citizen science; Author-Supplied Keyword: decision-making; Author-Supplied Keyword: government; Author-Supplied Keyword: strategy; Number of Pages: 9p; Document Type: Article | RAYYAN-INCLUSION: {"Philip"=>"Excluded", "Elina"=>"Excluded", "fereshteh"=>"Included", "Alec"=>"Excluded"} | R19: 10.5334/cstp.231 | S19: eppi-reviewer;CITIZEN;cience ACQUISITION of data DECISION making PILOT project;COMMUNITY involvement barrier;deci;ion-making government;trategy
A20: rayyan-83177428 | B20: Boundary Work: Engaging Knowledge Systems in Co-management of Feral Animals on Indigenous Lands | C20: 2012 | F20: Ecology & Society | H20: 17 | I20: 2 | J20: 387-399 | K20: Robinson Catherine J and Wallington Tabatha J | L20: http://0-search.ebscohost.com.catalogue.libraries.london.ac.uk/login.aspx?direct=true&db=a9h&AN=77928781&site=ehost-live | Q20: Robinson, Catherine J. 1 Wallington, Tabatha J. 1; Affiliation: 1: CSIRO Ecosystem Sciences; Source Info: 2012, Vol. 17 Issue 2, p387; Subject Term: FERAL animals; Subject Term: WILDLIFE conservation; Subject Term: TRADITIONAL ecological knowledge; Subject Term: ENVIRONMENTAL management; Subject Term: ENVIRONMENTAL protection; Subject Term: AUSTRALIA; Author-Supplied Keyword: co-benefits; Author-Supplied Keyword: co-managed boundary work; Author-Supplied Keyword: collaboration; Author-Supplied Keyword: environmental governance; Author-Supplied Keyword: feral animal management; Author-Supplied Keyword: Indigenous knowledge; Author-Supplied Keyword: knowledge-action systems; Number of Pages: 12p; Document Type: Article | RAYYAN-INCLUSION: {"Philip"=>"Excluded", "fereshteh"=>"Excluded", "Iris"=>"Included", "Alec"=>"Included"} | R20: 10.5751/ES-04836-170216 | S20: eppi-reviewer;FERAL animal;WILDLIFE con;ervation TRADITIONAL ecological knowledge ENVIRONMENTAL management ENVIRONMENTAL protection AUSTR...;co-managed boundary work collaboration environmental governance feral animal management Indigenou;knowledge knowledge-action;y;tem
A21: rayyan-83177429 | B21: Social process in grizzly bear management: lessons for collaborative governance and natural resource policy | C21: 2012 | F21: Policy Sciences | G21: 322687 | H21: 45 | I21: 3 | J21: 265-291 | K21: Richie Lauren and Oppenheimer J Daniel and Clark Susan G | L21: https://www.proquest.com/scholarly-journals/social-process-grizzly-bear-management-lessons/docview/1030728772/se-2?accountid=14511 https://ucl-new-primo.hosted.exlibrisgroup.com/openurl/UCL/UCL_VU2?url_ver=Z39.88-2004&rft_val_fmt=info:ofi/fmt:kev:mtx:journal&genre=article&sid=ProQ:ProQ%3Aibss&atitle=Social+process+in+grizzly+bear+management%3A+lessons+for+collaborative+governance+and+natural+resource+policy&title=Policy+Sciences&issn=00322687&date=2012-09-01&volume=45&issue=3&spage=265&au=Richi | Q21: Copyright - Springer Science+Business Media, LLC. 2012 CODEN - PLSCBZ SubjectsTermNotLitGenreText - Canada | RAYYAN-INCLUSION: {"Philip"=>"Excluded", "fereshteh"=>"Excluded", "Sarah"=>"Included", "Alec"=>"Included"} | R21: https://doi.org/10.1007/s11077-012-9160-z | S21: eppi-reviewer;Political Science;Natural resource management;Bears;Public policy;Analysis;Studies;Collaboration;National parks;Decision making;Canada;71219:Nature Parks and Other Similar Institutions;2600:Management science/operations research;9130:Experimental/theoretical;9172:Canada;1200:Social policy;1530:Natural resources
A22: rayyan-83177433 | B22: Evidence-informed policy and practice: The role and potential of civil society | C22: 2020 | F22: African Evaluation Journal | H22: 8 | I22: 1 | J22: 46327 | K22: Pabari Mine and Amisi Matodzi M and David-Gnahoui Emmanuel and Bedu-Addo Dede and Goldman Ian | L22: http://0-search.ebscohost.com.catalogue.libraries.london.ac.uk/login.aspx?direct=true&db=a9h&AN=148228034&site=ehost-live | Q22: Pabari, Mine 1; Email Address: mine.pabari@athariadvisory.co.ke Amisi, Matodzi M. 1 David-Gnahoui, Emmanuel 2 Bedu-Addo, Dede 3 Goldman, Ian 1; Affiliation: 1: CLEAR Anglophone Africa (CLEAR AA), Faculty of Commerce, Law and Management, University of the Witwatersrand, Johannesburg, South Africa 2: Faculty of Human and Social Sciences, University of Abomey-Calavi, Cotonou, Benin 3: Ghana Monitoring and Evaluation Forum (GMEF), Accra, Ghana; Source Info: 2020, Vol. 8 Issue 1, p1; Subject Term: CIVIL society; Subject Term: VIOLENCE against women; Subject Term: BEHAVIOR; Subject Term: CASE studies; Subject Term: BENIN; Subject Term: GHANA; Subject Term: KENYA; Author-Supplied Keyword: Citizen engagement; Author-Supplied Keyword: Civil society; Author-Supplied Keyword: Evidence use; Author-Supplied Keyword: Evidence-informed policymaking; Author-Supplied Keyword: Sustainable development; Number of Pages: 11p; Document Type: Article | RAYYAN-INCLUSION: {"Philip"=>"Excluded", "fereshteh"=>"Excluded", "Aidan"=>"Excluded", "Alec"=>"Included"} | R22: 10.4102/aej.v8i1.470 | S22: eppi-reviewer;CIVIL;ociety VIOLENCE again;t women BEHAVIOR CASE;tudie;BENIN GHANA KENYA Citizen engagement Evidence u;e Evidence-informed policymaking Su;tainable development
A23: rayyan-83177435 | B23: Pathways to impact for aquatic conservation science via multi-modal communication and stakeholder engagement | C23: 2020 | F23: Aquatic Conservation-Marine and Freshwater Ecosystems | G23: 1052-7613 | H23: 30 | I23: 9 | J23: 1791-1797 | K23: Noble M M and Fulton C J | L23: <Go to ISI>://WOS:000570237100014 | Q23: Noble, Mae M. Fulton, Christopher J. Fulton, Christopher J/A-5971-2008 Fulton, Christopher J/0000-0002-1140-1999 1099-0755 Si | RAYYAN-INCLUSION: {"Matthew"=>"Included", "Philip"=>"Included", "Alice"=>"Included", "Carlos"=>"Maybe", "Tabitha"=>"Included", "Prishnee"=>"Excluded", "Valentin"=>"Excluded", "Elina"=>"Included", "fereshteh"=>"Excluded", "Aidan"=>"Included", "Tiff"=>"Included", "Iris"=>"Included", "Sarah"=>"Included", "Nibedita"=>"Included", "Alec"=>"Included", "Isobel"=>"Included"} | R23: 10.1002/aqc.3380 | S23: eppi-reviewer
A24: rayyan-83177440 | B24: Use of web-based species occurrence information systems by academics and government professionals | C24: 2020 | F24: PLoS ONE [Electronic Resource] | H24: 15 | I24: 7 | J24: e0236556-e0236556 | K24: Martin-Mora E and Ellis S and Page L M | L24: https://ovidsp.ovid.com/ovidweb.cgi?T=JS&CSC=Y&NEWS=N&PAGE=fulltext&D=med18&AN=32735594 https://discover.lshtm.ac.uk/openurl/44HYG/44HYG_services_page?sid=OVID:medline&id=doi:10.1371%2Fjournal.pone.0236556&id=pmid32735594&issn=1932-6203&isbn=&volume=15&issue=7&spage=e0236556&pages=e0236556&date=2020&title=PLoS+ONE+%5BElectronic+Resource%5D&atitle=Use+of+web-based+species+occurrence+information+systems+by+academics+and+government+professionals.&aulast=Martin-Mora&pid=%3Cauthor%3EMartin-Mora+E%3BE | O24: Martin-Mora, Elizabeth. School of Natural Resources and Environment, University of Florida, Gainesvi | Q24: Martin-Mora, Elizabeth Ellis, Shari Page, Lawrence M | RAYYAN-INCLUSION: {"Matthew"=>"Included", "Philip"=>"Included", "Alice"=>"Included", "Carlos"=>"Excluded", "Tabitha"=>"Excluded", "Prishnee"=>"Excluded", "Valentin"=>"Included", "Elina"=>"Excluded", "fereshteh"=>"Excluded", "Aidan"=>"Included", "Tiff"=>"Excluded", "Iris"=>"Included", "Sarah"=>"Excluded", "Nibedita"=>"Excluded", "Alec"=>"Included", "Isobel"=>"Included"} | S24: eppi-reviewer
A25: rayyan-83177445 | B25: Stakeholder participation in IPBES: connecting local environmental work with global decision making | C25: 2020 | F25: Ecosystems and People | H25: 16 | I25: 1 | J25: 197-211 | K25: Krug Cornelia B and Sterling Eleanor and Cadman Timothy and Geschke Jonas and Drummond de Castro, Paula F and Schliep Rainer and Osemwegie Isimemen and Muller-Karger Frank E and Maraseni Tek | L25: https://ovidsp.ovid.com/ovidweb.cgi?T=JS&CSC=Y&NEWS=N&PAGE=fulltext&D=pmnm5&AN=32984823 https://discover.lshtm.ac.uk/openurl/44HYG/44HYG_services_page?sid=OVID:medline&id=doi:10.1080%2F26395916.2020.1788643&id=pmid32984823&issn=2639-5908&isbn=&volume=16&issue=1&spage=197&pages=197-211&date=2020&title=Ecosystems+and+People&atitle=Stakeholder+participation+in+IPBES%3A+connecting+local+environmental+work+with+global+decision+making.&aulast=Krug&pid=%3Cauthor%3EKrug+CB%3BSterling+E%3BCadman+T%3BGesc | O25: Krug, Cornelia B. bioDISCOVERY, Department of Geography, University of Zurich, Zurich, Switzerland. | Q25: Krug CB Sterling E Cadman T Geschke J Drummond de Castro PF Schliep R Osemwegie I Muller-Karger FE Maraseni T | RAYYAN-INCLUSION: {"Philip"=>"Excluded", "Carlos"=>"Included", "Elina"=>"Excluded", "fereshteh"=>"Included"} | S25: eppi-reviewer
A26: rayyan-83177449 | B26: Improving technical information use: what can be learnt from a manager's perspective? | C26: 2013 | F26: Environmental Management | H26: 52 | I26: 1 | J26: 221-233 | K26: Jacobson C and Lisle A and Carter R W and Hockings M T | L26: https://ovidsp.ovid.com/ovidweb.cgi?T=JS&CSC=Y&NEWS=N&PAGE=fulltext&D=med10&AN=23728487 https://discover.lshtm.ac.uk/openurl/44HYG/44HYG_services_page?sid=OVID:medline&id=doi:10.1007%2Fs00267-013-0084-y&id=pmid23728487&issn=0364-152X&isbn=&volume=52&issue=1&spage=221&pages=221-33&date=2013&title=Environmental+Management&atitle=Improving+technical+information+use%3A+what+can+be+learnt+from+a+manager%27s+perspective%3F.&aulast=Jacobson&pid=%3Cauthor%3EJacobson+C%3BLisle+A%3BCarter+RW%3BHockings+MT | O26: Jacobson, C. Sustainability Research Centre, University of the Sunshine Coast, Maroochydore DC, Lock | Q26: Jacobson, C Lisle, A Carter, R W Hockings, M T | RAYYAN-INCLUSION: {"Matthew"=>"Included", "Philip"=>"Included", "Alice"=>"Included", "Carlos"=>"Included", "Tabitha"=>"Included", "Prishnee"=>"Included", "Valentin"=>"Excluded", "Elina"=>"Included", "fereshteh"=>"Excluded", "Aidan"=>"Included", "Tiff"=>"Included", "Iris"=>"Included", "Sarah"=>"Included", "Nibedita"=>"Excluded", "Alec"=>"Included", "Isobel"=>"Included"} | S26: eppi-reviewer
A27: rayyan-83177453 | B27: Science Collaboration for Capacity Building: Advancing Technology Transfer Through a Treaty for Biodiversity Beyond National Jurisdiction | C27: 2020 | F27: Frontiers in Marine Science | H27: 7 | K27: Harden-Davies H and Snelgrove P | L27: <Go to ISI>://WOS:000517576400001 | Q27: Harden-Davies, Harriet Snelgrove, Paul Harden-Davies, Harriet/0000-0002-8214-5187 2296-7745 | RAYYAN-INCLUSION: {"Philip"=>"Excluded", "Carlos"=>"Excluded", "Elina"=>"Excluded", "fereshteh"=>"Included"} | R27: 10.3389/fmars.2020.00040 | S27: eppi-reviewer
A28: rayyan-83177455 | B28: The ecosystem approach as a framework for understanding knowledge utilisation | C28: 2014 | F28: ENVIRONMENT AND PLANNING C-GOVERNMENT AND POLICY | H28: 32 | I28: 2 | J28: 301-319 | K28: Haines-Young Roy and Potschin Marion | N28: SAGE PUBLICATIONS LTD | O28: 1 OLIVERS YARD, 55 CITY ROAD, LONDON EC1Y 1SP, ENGLAND | Q28: RAYYAN-INCLUSION: {"Philip"=>"Excluded", "Carlos"=>"Excluded", "fereshteh"=>"Excluded"} | R28: 10.1068/c1329j | S28: eppi-reviewer;eco;y;tem approach;knowledge utili;ation and inno
A29: rayyan-83177457 | B29: The role of boundary organizations in co-management: examining the politics of knowledge integration in a marine protected area in Belize | C29: 2016 | F29: International Journal of the Commons | G29: 1875-0281 | H29: 10 | I29: 2 | J29: 1013-1034 | K29: Gray N J | L29: <Go to ISI>://WOS:000388648200025 | Q29: Gray, Noella J. Annual Conference of the American-Anthropological-Association 2013 Chicago, IL Amer Anthropol Assoc | RAYYAN-INCLUSION: {"Matthew"=>"Included", "Philip"=>"Included", "fereshteh"=>"Included"} | R29: 10.18352/ijc.643 | S29: eppi-reviewer
A30: rayyan-83177458 | B30: Data selection for making biodiversity management decisions: Best available science and institutionalized agency norms | C30: 2013 | F30: Administration & Society | H30: 45 | I30: 2 | J30: 213-241 | K30: Gerlach John David and Williams Laron K and Forcina Colleen E | L30: https://ovidsp.ovid.com/ovidweb.cgi?T=JS&CSC=Y&NEWS=N&PAGE=fulltext&D=psyc10&AN=2013-15898-005 https://discover.lshtm.ac.uk/openurl/44HYG/44HYG_services_page?sid=OVID:psycdb&id=doi:10.1177%2F0095399712451886&id=pmid&issn=0095-3997&isbn=&volume=45&issue=2&spage=213&pages=213-241&date=2013&title=Administration+%26+Society&atitle=Data+selection+for+making+biodiversity+management+decisions%3A+Best+available+science+and+institutionalized+agency+norms.&aulast=Gerlach&pid=%3Cauthor%3EGerlach%2C+John+D | Q30: RAYYAN-INCLUSION: {"Philip"=>"Included", "Alice"=>"Included", "fereshteh"=>"Included"} | S30: eppi-reviewer
A31: rayyan-83177461 | B31: Exploring connections among the multiple outputs and outcomes emerging from 25 years of sea turtle conservation in Northern Cyprus | C31: 2020 | F31: Journal for Nature Conservation | G31: 1617-1381 | H31: 55 | K31: Edwards R C and Godley B J and Nuno A | L31: <Go to ISI>://WOS:000536928400016 | Q31: Edwards, Rachael C. Godley, Brendan J. Nuno, Ana Nuno, Ana/H-9497-2019 Nuno, Ana/0000-0003-4680-2378; Edwards, Rachael Catherine/0000-0003-4717-7615 1618-1093 | RAYYAN-INCLUSION: {"Matthew"=>"Included", "Philip"=>"Excluded", "fereshteh"=>"Included"} | R31: 10.1016/j.jnc.2020.125816 | S31: eppi-reviewer
A32: rayyan-83177462 | B32: Red lists in conservation science-policy interfaces: A case study from Vietnam | C32: 2018 | F32: Biological Conservation | H32: 226 | J32: 101-110 | K32: Do Thi Huong and Krott Max and Juerges Nataly and BÃ¶cher Michael | L32: http://0-search.ebscohost.com.catalogue.libraries.london.ac.uk/login.aspx?direct=true&db=a9h&AN=131628516&site=ehost-live | Q32: Do, Thi Huong 1; Email Address: dohuongnlkh@gmail.com Krott, Max 1 Juerges, Nataly 1 BÃ¶cher, Michael 1; Affiliation: 1: Chair Group of Forest and Nature Conservation Policy, George-August University of GÃ¶ttingen, BÃ¼sgenweg 3, 37077 GÃ¶ttingen, Germany; Source Info: Oct2018, Vol. 226, p101; Subject Term: ENDANGERED species; Subject Term: BIODIVERSITY conservation; Subject Term: KNOWLEDGE transfer; Subject Term: CONSERVATION biology; Author-Supplied Keyword: Biodiversity conservation; Author-Supplied Keyword: Red lists; Author-Supplied Keyword: RIU model; Author-Supplied Keyword: Scienceâ€“policy interface; Author-Supplied Keyword: Science-based policy advice; Author-Supplied Keyword: Vietnamese Red Data Book; Reviews &amp; Products: RED data book; Number of Pages: 10p; Document Type: Article | RAYYAN-INCLUSION: {"Philip"=>"Included", "fereshteh"=>"Included", "Nibedita"=>"Included"} | R32: 10.1016/j.biocon.2018.07.016 | S32: eppi-reviewer;ENDANGERED;pecie;BIODIVERSITY con;ervation KNOWLEDGE tran;fer CONSERVATION biology Red li;t;RIU model Scienceâ€“policy interface Science-ba;ed policy advice Vietname;e Red Data Book RED data book
A33: rayyan-83177463 | B33: Toward successful implementation of conservation research: A case study from Vietnam | C33: 2018 | F33: Ambio | H33: 47 | I33: 5 | J33: 608-621 | K33: Do Thi and H and Krott M and Bocher M and Juerges N | L33: https://ovidsp.ovid.com/ovidweb.cgi?T=JS&CSC=Y&NEWS=N&PAGE=fulltext&D=med15&AN=29264868 https://discover.lshtm.ac.uk/openurl/44HYG/44HYG_services_page?sid=OVID:medline&id=doi:10.1007%2Fs13280-017-0999-2&id=pmid29264868&issn=0044-7447&isbn=&volume=47&issue=5&spage=608&pages=608-621&date=2018&title=Ambio&atitle=Toward+successful+implementation+of+conservation+research%3A+A+case+study+from+Vietnam.&aulast=Do+Thi&pid=%3Cauthor%3EDo+Thi+H%3BKrott+M%3BBocher+M%3BJuerges+N%3C%2Fauthor%3E%3CAN%3E2926486 | O33: Do Thi, Huong. Chair Group of Forest and Nature Conservation Policy, George-August University of Got | Q33: Do Thi, Huong Krott, Max Bocher, Michael Juerges, Nataly | RAYYAN-INCLUSION: {"Philip"=>"Excluded", "Carlos"=>"Included", "Elina"=>"Included", "fereshteh"=>"Included"} | S33: eppi-reviewer
A34: rayyan-83177464 | B34: What works in conservation? Using expert assessment of summarised evidence to identify practices that enhance natural pest control in agriculture | C34: 2016 | F34: Biodiversity & Conservation | H34: 25 | I34: 7 | J34: 1383-1399 | K34: Dicks Lynn V and Wright Hugh L and Ashpole Joscelyne E and Hutchison James and McCormack Caitlin G and Livoreil Barbara and Zulka Klaus Peter and Sutherland William J | L34: https://ovidsp.ovid.com/ovidweb.cgi?T=JS&CSC=Y&NEWS=N&PAGE=fulltext&D=pmnm3&AN=32355426 https://discover.lshtm.ac.uk/openurl/44HYG/44HYG_services_page?sid=OVID:medline&id=doi:10.1007%2Fs10531-016-1133-7&id=pmid32355426&issn=0960-3115&isbn=&volume=25&issue=7&spage=1383&pages=1383-1399&date=2016&title=Biodiversity+%26+Conservation&atitle=What+works+in+conservation%3F+Using+expert+assessment+of+summarised+evidence+to+identify+practices+that+enhance+natural+pest+control+in+agriculture.&aulast=Dicks& | O34: Dicks, Lynn V. 1Department of Zoology, University of Cambridge, Cambridge, CB2 3QZ UK. Wright, Hugh | Q34: Dicks LV Wright HL Ashpole JE Hutchison J McCormack CG Livoreil B Zulka KP Sutherland WJ | RAYYAN-INCLUSION: {"Matthew"=>"Included", "Philip"=>"Excluded", "fereshteh"=>"Included"} | S34: eppi-reviewer
A35: rayyan-83177466 | B35: Comparing student and professional responses toward advocacy in science | C35: 2016 | F35: Human Dimensions of Wildlife | H35: 21 | I35: 4 | J35: 361-370 | K35: Crawford Brian A and Kramer David W and Hinton Joseph W | L35: https://ovidsp.ovid.com/ovidweb.cgi?T=JS&CSC=Y&NEWS=N&PAGE=fulltext&D=psyc13&AN=2016-26995-007 https://discover.lshtm.ac.uk/openurl/44HYG/44HYG_services_page?sid=OVID:psycdb&id=doi:10.1080%2F10871209.2016.1149747&id=pmid&issn=1087-1209&isbn=&volume=21&issue=4&spage=361&pages=361-370&date=2016&title=Human+Dimensions+of+Wildlife&atitle=Comparing+student+and+professional+responses+toward+advocacy+in+science.&aulast=Crawford&pid=%3Cauthor%3ECrawford%2C+Brian+A%3BKramer%2C+David+W%3BHinton%2C+Joseph | Q35: RAYYAN-INCLUSION: {"Philip"=>"Excluded", "fereshteh"=>"Excluded"} | S35: eppi-reviewer
A36: rayyan-83177468 | B36: Governance Challenges in Joint Inter-Jurisdictional Management: The Grand Teton National Park, Wyoming, Elk Case | C36: 2015 | F36: Environmental Management | H36: 56 | I36: 2 | J36: 286-299 | K36: Clark S G and Vernon M E | L36: https://ovidsp.ovid.com/ovidweb.cgi?T=JS&CSC=Y&NEWS=N&PAGE=fulltext&D=med12&AN=25904468 https://discover.lshtm.ac.uk/openurl/44HYG/44HYG_services_page?sid=OVID:medline&id=doi:10.1007%2Fs00267-015-0515-z&id=pmid25904468&issn=0364-152X&isbn=&volume=56&issue=2&spage=286&pages=286-99&date=2015&title=Environmental+Management&atitle=Governance+Challenges+in+Joint+Inter-Jurisdictional+Management%3A+The+Grand+Teton+National+Park%2C+Wyoming%2C+Elk+Case.&aulast=Clark&pid=%3Cauthor%3EClark+SG%3BVernon+ME%3 | O36: Clark, Susan G. School of Forestry and Environmental Studies, Yale University, 195 Prospect, New Hav | Q36: Clark, Susan G Vernon, Marian E | RAYYAN-INCLUSION: {"Philip"=>"Excluded", "fereshteh"=>"Included", "Sarah"=>"Included"} | S36: eppi-reviewer
A37: rayyan-83177469 | B37: Wyoming sage-grouse working groups: lessons learned | C37: 2017 | F37: Human-Wildlife Interactions | G37: 1934-4392 | H37: 11 | I37: 3 | J37: 274-286 | K37: Christiansen T J and Belton L R | L37: <Go to ISI>://WOS:000422844800012 | Q37: Christiansen, Thomas J. Belton, Lorien R. 1936-8046 | RAYYAN-INCLUSION: {"fereshteh"=>"Excluded"} | S37: eppi-reviewer
A38: rayyan-83177470 | B38: Creating a biodiversity science community: Experiences from a European Network of Knowledge | C38: 2015 | F38: Environmental Science and Policy | H38: 54 | J38: 497-504 | K38: Carmen E and Nesshover C and Saarikoski H and Vandewalle M and Watt A and Wittmer H and Young J | L38: https://ovidsp.ovid.com/ovidweb.cgi?T=JS&CSC=Y&NEWS=N&PAGE=fulltext&D=emed16&AN=603965883 https://discover.lshtm.ac.uk/openurl/44HYG/44HYG_services_page?sid=OVID:embase&id=doi:10.1016%2Fj.envsci.2015.03.014&id=pmid&issn=1462-9011&isbn=&volume=54&issue=&spage=497&pages=497-504&date=2015&title=Environmental+Science+and+Policy&atitle=Creating+a+biodiversity+science+community%3A+Experiences+from+a+European+Network+of+Knowledge&aulast=Carmen&pid=%3Cauthor%3ECarmen+E.%3BNesshover+C.%3BSaarikoski+H.%3 | Q38: RAYYAN-INCLUSION: {"Philip"=>"Included", "fereshteh"=>"Included", "Nibedita"=>"Excluded"} | S38: eppi-reviewer
A39: rayyan-83177471 | B39: A tenuous link: Information transfer between urban ecological research and restoration practice | C39: 2021 | F39: Urban Forestry & Urban Greening | G39: 1618-8667 | H39: 60 | K39: Busbridge S and Clarkson B D and Wallace K J | L39: <Go to ISI>://WOS:000636302300005 | Q39: Busbridge, Sarah Clarkson, Bruce D. Wallace, K. J. 1610-8167 | RAYYAN-INCLUSION: {"Philip"=>"Included", "fereshteh"=>"Excluded", "Iris"=>"Included"} | R39: 10.1016/j.ufug.2021.127019 | S39: eppi-reviewer
A40: rayyan-83177472 | B40: Rural local institutions and climate change adaptation in forest communities in Cameroon | C40: 2015 | F40: Ecology and Society | G40: 1708-3087 | H40: 20 | I40: 2 | K40: Brown H C. P and Sonwa D J | L40: <Go to ISI>://WOS:000357622800007 | Q40: Brown, H. Carolyn Peach Sonwa, Denis J. | RAYYAN-INCLUSION: {"Tabitha"=>"Excluded", "fereshteh"=>"Excluded"} | R40: 10.5751/es-07327-200206 | S40: eppi-reviewer
...

Sheet Sheet1
A1: Rayyan_key | B1: authors | C1: year | D1: title | E1: journal | F1: volume | G1: issue | H1: pages | I1: doi
A2: rayyan-83178000 | B2: =VLOOKUP($A2,articles_2026_01_26!$A$2:$U$737,11,FALSE) -> Barrett Kyle and Rodriguez Shari L | C2: =VLOOKUP($A2,articles_2026_01_26!$A$2:$U$737,3,FALSE) -> 2021 | D2: =VLOOKUP($A2,articles_2026_01_26!$A$2:$U$737,2,FALSE) -> What Sources Are Natural Resource Managers Using to Make Decisions? | E2: =VLOOKUP($A2,articles_2026_01_26!$A$2:$U$737,6,FALSE) -> Journal of Wildlife Management | F2: =VLOOKUP($A2,articles_2026_01_26!$A$2:$U$737,8,FALSE) -> 85 | G2: =VLOOKUP($A2,articles_2026_01_26!$A$2:$U$737,9,FALSE) -> 8 | H2: =VLOOKUP($A2,articles_2026_01_26!$A$2:$U$737,10,FALSE) -> 1543-1553 | I2: =VLOOKUP($A2,articles_2026_01_26!$A$2:$U$737,18,FALSE) -> 10.1002/jwmg.22112
A3: rayyan-83177408 | B3: =VLOOKUP($A3,articles_2026_01_26!$A$2:$U$737,11,FALSE) -> Weiskopf S R and Harmackova Z V and Johnson C G and Londono-Murcia M C and Miller B W and Myers B J. E and Pereira L and Arce-Plata M I and Blanchard J L and Ferrier S and Fulton E A and Harfoot M and Isbell F and Johnson J A and Mori A S and Weng E S and Rosa I M. D | C3: =VLOOKUP($A3,articles_2026_01_26!$A$2:$U$737,3,FALSE) -> 2022 | D3: =VLOOKUP($A3,articles_2026_01_26!$A$2:$U$737,2,FALSE) -> Increasing the uptake of ecological model results in policy decisions to improve biodiversity outcomes | E3: =VLOOKUP($A3,articles_2026_01_26!$A$2:$U$737,6,FALSE) -> Environmental Modelling & Software | F3: =VLOOKUP($A3,articles_2026_01_26!$A$2:$U$737,8,FALSE) -> 149 | G3: =VLOOKUP($A3,articles_2026_01_26!$A$2:$U$737,9,FALSE) -> 0 | H3: =VLOOKUP($A3,articles_2026_01_26!$A$2:$U$737,10,FALSE) -> 0 | I3: =VLOOKUP($A3,articles_2026_01_26!$A$2:$U$737,18,FALSE) -> 10.1016/j.envsoft.2022.105318
A4: rayyan-83177414 | B4: =VLOOKUP($A4,articles_2026_01_26!$A$2:$U$737,11,FALSE) -> Toomey Anne H and Alvaro MarÃ­a Eugenia Copa and Aiello-Lammens Matthew and Loayza Cossio and Oscar and Barlow Jos | C4: =VLOOKUP($A4,articles_2026_01_26!$A$2:$U$737,3,FALSE) -> 2019 | D4: =VLOOKUP($A4,articles_2026_01_26!$A$2:$U$737,2,FALSE) -> A question of dissemination: Assessing the practices and implications of research in tropical landscapes | E4: =VLOOKUP($A4,articles_2026_01_26!$A$2:$U$737,6,FALSE) -> AMBIO - A Journal of the Human Environment | F4: =VLOOKUP($A4,articles_2026_01_26!$A$2:$U$737,8,FALSE) -> 48 | G4: =VLOOKUP($A4,articles_2026_01_26!$A$2:$U$737,9,FALSE) -> 1 | H4: =VLOOKUP($A4,articles_2026_01_26!$A$2:$U$737,10,FALSE) -> 35-47 | I4: =VLOOKUP($A4,articles_2026_01_26!$A$2:$U$737,18,FALSE) -> 10.1007/s13280-018-1056-5
A5: rayyan-83177415 | B5: =VLOOKUP($A5,articles_2026_01_26!$A$2:$U$737,11,FALSE) -> Taylor C and Cockburn J and Rouget M and Ray-Mukherjee J and Mukherjee S and Slotow R and Roberts D and Boon R and O'Donoghue S and Douwes E | C5: =VLOOKUP($A5,articles_2026_01_26!$A$2:$U$737,3,FALSE) -> 2016 | D5: =VLOOKUP($A5,articles_2026_01_26!$A$2:$U$737,2,FALSE) -> lEvaluating the outcomes and processes of a research-action partnership: The need for continuous reflective evaluation | E5: =VLOOKUP($A5,articles_2026_01_26!$A$2:$U$737,6,FALSE) -> Bothalia | F5: =VLOOKUP($A5,articles_2026_01_26!$A$2:$U$737,8,FALSE) -> 46 | G5: =VLOOKUP($A5,articles_2026_01_26!$A$2:$U$737,9,FALSE) -> 2 | H5: =VLOOKUP($A5,articles_2026_01_26!$A$2:$U$737,10,FALSE) -> 0 | I5: =VLOOKUP($A5,articles_2026_01_26!$A$2:$U$737,18,FALSE) -> 10.4102/abc.v46i2.2154
A6: rayyan-83177416 | B6: =VLOOKUP($A6,articles_2026_01_26!$A$2:$U$737,11,FALSE) -> Taft Heather R and McCoskey Dana N and Miller Joshua M and Pearson Sarah K and Coleman Melinda A and Fletcher Nicholas K and Mittan Cinnamon S and Meek Mariah H and Barbosa Soraia | C6: =VLOOKUP($A6,articles_2026_01_26!$A$2:$U$737,3,FALSE) -> 2020 | D6: =VLOOKUP($A6,articles_2026_01_26!$A$2:$U$737,2,FALSE) -> Researchâ€“management partnerships: An opportunity to integrate genetics in conservation actions | E6: =VLOOKUP($A6,articles_2026_01_26!$A$2:$U$737,6,FALSE) -> Conservation Science & Practice | F6: =VLOOKUP($A6,articles_2026_01_26!$A$2:$U$737,8,FALSE) -> 2 | G6: =VLOOKUP($A6,articles_2026_01_26!$A$2:$U$737,9,FALSE) -> 9 | H6: =VLOOKUP($A6,articles_2026_01_26!$A$2:$U$737,10,FALSE) -> 46235 | I6: =VLOOKUP($A6,articles_2026_01_26!$A$2:$U$737,18,FALSE) -> 10.1111/csp2.218
A7: rayyan-83177418 | B7: =VLOOKUP($A7,articles_2026_01_26!$A$2:$U$737,11,FALSE) -> Suskevics M and Raadom T and Vanem B and Kana S and Roasto R and Runnel V and Kulvik M | C7: =VLOOKUP($A7,articles_2026_01_26!$A$2:$U$737,3,FALSE) -> 2021 | D7: =VLOOKUP($A7,articles_2026_01_26!$A$2:$U$737,2,FALSE) -> Challenges and opportunities of engaging biodiversity-related citizen science data in environmental decision-making: Practitioners' perceptions and a database analysis from Estonia | E7: =VLOOKUP($A7,articles_2026_01_26!$A$2:$U$737,6,FALSE) -> Journal for Nature Conservation | F7: =VLOOKUP($A7,articles_2026_01_26!$A$2:$U$737,8,FALSE) -> 64 | G7: =VLOOKUP($A7,articles_2026_01_26!$A$2:$U$737,9,FALSE) -> 0 | H7: =VLOOKUP($A7,articles_2026_01_26!$A$2:$U$737,10,FALSE) -> 0 | I7: =VLOOKUP($A7,articles_2026_01_26!$A$2:$U$737,18,FALSE) -> 10.1016/j.jnc.2021.126068
A8: rayyan-83177421 | B8: =VLOOKUP($A8,articles_2026_01_26!$A$2:$U$737,11,FALSE) -> Stephenson P J and Bowles-Newark Nadine and Regan Eugenie and Stanwell-Smith Damon and Diagana MallÃ© and HÃ¶ft Robert and Abarchi Harouna and Abrahamse Tanya and Akello Christine and Allison Hilary and Banki Olaf and Batieno Barthelemy and Dieme Samuel and Domingos Arthur and Galt Russell and Githaiga Cicilia W and Guindo Abdoulaye Bine and Hafashimana David L N and Hirsch Tim and Hobern Donald | C8: =VLOOKUP($A8,articles_2026_01_26!$A$2:$U$737,3,FALSE) -> 2017 | D8: =VLOOKUP($A8,articles_2026_01_26!$A$2:$U$737,2,FALSE) -> Unblocking the flow of biodiversity data for decision-making in Africa | E8: =VLOOKUP($A8,articles_2026_01_26!$A$2:$U$737,6,FALSE) -> Biological Conservation | F8: =VLOOKUP($A8,articles_2026_01_26!$A$2:$U$737,8,FALSE) -> 213 | G8: =VLOOKUP($A8,articles_2026_01_26!$A$2:$U$737,9,FALSE) -> 0 | H8: =VLOOKUP($A8,articles_2026_01_26!$A$2:$U$737,10,FALSE) -> 335-340 | I8: =VLOOKUP($A8,articles_2026_01_26!$A$2:$U$737,18,FALSE) -> 10.1016/j.biocon.2016.09.003
A9: rayyan-83177422 | B9: =VLOOKUP($A9,articles_2026_01_26!$A$2:$U$737,11,FALSE) -> Sitas N and Harmackova Z V and Anticamara J A and Arneth A and Badola R and Biggs R and Blanchard R and Brotons L and Cantele M and Coetzer K and DasGupta R and den Belder E and Ghosh S and Guisan A and Gundimeda H and Hamann M and Harrison P A and Hashimoto S and Hauck J and Klatt B J and Kok K and Krug R M and Niamir A and O'Farrell P J and Okayasu S and Palomo I and Pereira L M and Riordan P and Santos-Martin F and Selomane O and Shin Y J and Valle M | C9: =VLOOKUP($A9,articles_2026_01_26!$A$2:$U$737,3,FALSE) -> 2019 | D9: =VLOOKUP($A9,articles_2026_01_26!$A$2:$U$737,2,FALSE) -> Exploring the usefulness of scenario archetypes in science-policy processes: experience across IPBES assessments | E9: =VLOOKUP($A9,articles_2026_01_26!$A$2:$U$737,6,FALSE) -> Ecology and Society | F9: =VLOOKUP($A9,articles_2026_01_26!$A$2:$U$737,8,FALSE) -> 24 | G9: =VLOOKUP($A9,articles_2026_01_26!$A$2:$U$737,9,FALSE) -> 3 | H9: =VLOOKUP($A9,articles_2026_01_26!$A$2:$U$737,10,FALSE) -> 0 | I9: =VLOOKUP($A9,articles_2026_01_26!$A$2:$U$737,18,FALSE) -> 10.5751/es-11039-240335
A10: rayyan-83177423 | B10: =VLOOKUP($A10,articles_2026_01_26!$A$2:$U$737,11,FALSE) -> Shiffman D S and Macdonald C C and Wallace S S and Dulvy N K | C10: =VLOOKUP($A10,articles_2026_01_26!$A$2:$U$737,3,FALSE) -> 2021 | D10: =VLOOKUP($A10,articles_2026_01_26!$A$2:$U$737,2,FALSE) -> The role and value of science in shark conservation advocacy | E10: =VLOOKUP($A10,articles_2026_01_26!$A$2:$U$737,6,FALSE) -> Scientific Reports | F10: =VLOOKUP($A10,articles_2026_01_26!$A$2:$U$737,8,FALSE) -> 11 | G10: =VLOOKUP($A10,articles_2026_01_26!$A$2:$U$737,9,FALSE) -> 1 | H10: =VLOOKUP($A10,articles_2026_01_26!$A$2:$U$737,10,FALSE) -> 16626-16626 | I10: =VLOOKUP($A10,articles_2026_01_26!$A$2:$U$737,18,FALSE) -> 0
